Workbook

Sheet Summary
A1: Crafty Puns: Topical Map Summary
A2: Priorities are qualitative (competitor coverage + seasonality). Validate with keyword volumes in Semrush/Ahrefs before scheduling.
A4: Hub | B4: Pages | C4: P1 | D4: P2 | E4: P3 | F4: Live (verified)
A5: Animal Puns | B5: =COUNTIF('Topical Map'!$B:$B,$A5) -> 54 | C5: =COUNTIFS('Topical Map'!$B:$B,$A5,'Topical Map'!$H:$H,"P1") -> 3 | D5: =COUNTIFS('Topical Map'!$B:$B,$A5,'Topical Map'!$H:$H,"P2") -> 28 | E5: =COUNTIFS('Topical Map'!$B:$B,$A5,'Topical Map'!$H:$H,"P3") -> 23 | F5: =COUNTIFS('Topical Map'!$B:$B,$A5,'Topical Map'!$J:$J,"Live (verified)") -> 4
A6: Food & Drink Puns | B6: =COUNTIF('Topical Map'!$B:$B,$A6) -> 47 | C6: =COUNTIFS('Topical Map'!$B:$B,$A6,'Topical Map'!$H:$H,"P1") -> 6 | D6: =COUNTIFS('Topical Map'!$B:$B,$A6,'Topical Map'!$H:$H,"P2") -> 23 | E6: =COUNTIFS('Topical Map'!$B:$B,$A6,'Topical Map'!$H:$H,"P3") -> 18 | F6: =COUNTIFS('Topical Map'!$B:$B,$A6,'Topical Map'!$J:$J,"Live (verified)") -> 2
A7: Nature & Science Puns | B7: =COUNTIF('Topical Map'!$B:$B,$A7) -> 36 | C7: =COUNTIFS('Topical Map'!$B:$B,$A7,'Topical Map'!$H:$H,"P1") -> 1 | D7: =COUNTIFS('Topical Map'!$B:$B,$A7,'Topical Map'!$H:$H,"P2") -> 20 | E7: =COUNTIFS('Topical Map'!$B:$B,$A7,'Topical Map'!$H:$H,"P3") -> 15 | F7: =COUNTIFS('Topical Map'!$B:$B,$A7,'Topical Map'!$J:$J,"Live (verified)") -> 5
A8: Holiday & Event Puns | B8: =COUNTIF('Topical Map'!$B:$B,$A8) -> 27 | C8: =COUNTIFS('Topical Map'!$B:$B,$A8,'Topical Map'!$H:$H,"P1") -> 5 | D8: =COUNTIFS('Topical Map'!$B:$B,$A8,'Topical Map'!$H:$H,"P2") -> 14 | E8: =COUNTIFS('Topical Map'!$B:$B,$A8,'Topical Map'!$H:$H,"P3") -> 8 | F8: =COUNTIFS('Topical Map'!$B:$B,$A8,'Topical Map'!$J:$J,"Live (verified)") -> 0
A9: Object & Everyday Puns | B9: =COUNTIF('Topical Map'!$B:$B,$A9) -> 17 | C9: =COUNTIFS('Topical Map'!$B:$B,$A9,'Topical Map'!$H:$H,"P1") -> 0 | D9: =COUNTIFS('Topical Map'!$B:$B,$A9,'Topical Map'!$H:$H,"P2") -> 5 | E9: =COUNTIFS('Topical Map'!$B:$B,$A9,'Topical Map'!$H:$H,"P3") -> 12 | F9: =COUNTIFS('Topical Map'!$B:$B,$A9,'Topical Map'!$J:$J,"Live (verified)") -> 2
A10: Sport & Hobby Puns | B10: =COUNTIF('Topical Map'!$B:$B,$A10) -> 25 | C10: =COUNTIFS('Topical Map'!$B:$B,$A10,'Topical Map'!$H:$H,"P1") -> 1 | D10: =COUNTIFS('Topical Map'!$B:$B,$A10,'Topical Map'!$H:$H,"P2") -> 19 | E10: =COUNTIFS('Topical Map'!$B:$B,$A10,'Topical Map'!$H:$H,"P3") -> 5 | F10: =COUNTIFS('Topical Map'!$B:$B,$A10,'Topical Map'!$J:$J,"Live (verified)") -> 0
A11: Work & School Puns | B11: =COUNTIF('Topical Map'!$B:$B,$A11) -> 10 | C11: =COUNTIFS('Topical Map'!$B:$B,$A11,'Topical Map'!$H:$H,"P1") -> 0 | D11: =COUNTIFS('Topical Map'!$B:$B,$A11,'Topical Map'!$H:$H,"P2") -> 3 | E11: =COUNTIFS('Topical Map'!$B:$B,$A11,'Topical Map'!$H:$H,"P3") -> 7 | F11: =COUNTIFS('Topical Map'!$B:$B,$A11,'Topical Map'!$J:$J,"Live (verified)") -> 0
A12: Fantasy & Pop Culture Puns | B12: =COUNTIF('Topical Map'!$B:$B,$A12) -> 8 | C12: =COUNTIFS('Topical Map'!$B:$B,$A12,'Topical Map'!$H:$H,"P1") -> 0 | D12: =COUNTIFS('Topical Map'!$B:$B,$A12,'Topical Map'!$H:$H,"P2") -> 4 | E12: =COUNTIFS('Topical Map'!$B:$B,$A12,'Topical Map'!$H:$H,"P3") -> 4 | F12: =COUNTIFS('Topical Map'!$B:$B,$A12,'Topical Map'!$J:$J,"Live (verified)") -> 0
A13: People & Relationship Puns | B13: =COUNTIF('Topical Map'!$B:$B,$A13) -> 13 | C13: =COUNTIFS('Topical Map'!$B:$B,$A13,'Topical Map'!$H:$H,"P1") -> 1 | D13: =COUNTIFS('Topical Map'!$B:$B,$A13,'Topical Map'!$H:$H,"P2") -> 6 | E13: =COUNTIFS('Topical Map'!$B:$B,$A13,'Topical Map'!$H:$H,"P3") -> 6 | F13: =COUNTIFS('Topical Map'!$B:$B,$A13,'Topical Map'!$J:$J,"Live (verified)") -> 0
A14: Word & Name Puns | B14: =COUNTIF('Topical Map'!$B:$B,$A14) -> 8 | C14: =COUNTIFS('Topical Map'!$B:$B,$A14,'Topical Map'!$H:$H,"P1") -> 1 | D14: =COUNTIFS('Topical Map'!$B:$B,$A14,'Topical Map'!$H:$H,"P2") -> 5 | E14: =COUNTIFS('Topical Map'!$B:$B,$A14,'Topical Map'!$H:$H,"P3") -> 2 | F14: =COUNTIFS('Topical Map'!$B:$B,$A14,'Topical Map'!$J:$J,"Live (verified)") -> 0
A15: Total topic pages | B15: =SUM(B5:B14) -> 245 | C15: =SUM(C5:C14) -> 18 | D15: =SUM(D5:D14) -> 127 | E15: =SUM(E5:E14) -> 100 | F15: =SUM(F5:F14) -> 13
A17: Use hub pages | B17: =COUNTA('Use Hubs'!A:A)-1 -> 13
A18: Outer section pages | B18: =COUNTA('Outer Section'!A:A)-1 -> 19
A19: Grand total pages | B19: =B15+B17+B18 -> 277
A21: Legend
A22: P1 | B22: Evergreen head topics every major pun site covers, or high-value use hubs. Build first.
A23: P2 | B23: Secondary topics with clear demand. Build after P1 hubs are complete.
A24: P3 | B24: Long-tail topics. Build to push topical coverage past 60%.
A25: Live (verified) | B25: Seen indexed on craftypuns.net during this research. Other existing pages may not be marked; update column J.
A26: Editable cells | B26: Topical Map columns H (Priority) and J (Status) have dropdowns; the Summary updates automatically.
A27: [N]+ counts | B27: Targets by priority (P1 200+, P2 150+, P3 100+). Change H1, meta title and description to the page's real count before publishing.
A28: Length checks | B28: Title Length turns red above 60 characters; Desc Length turns red above 155.
A30: Posts vs Pages
A31: Topic posts | B31: =COUNTA('Topical Map'!D:D)-1 -> 245
A32: Use hub posts | B32: =COUNTA('Use Hubs'!A:A)-1 -> 13
A33: Outer section posts | B33: =COUNTA('Outer Section'!A:A)-1 -> 19
A34: Total posts | B34: =SUM(B31:B33) -> 277
A35: Hub pages | B35: =COUNTIF('Site Pages'!A:A,"Hub") -> 10
A36: Sub-hub pages (new) | B36: =COUNTIFS('Site Pages'!A:A,"Sub-hub",'Site Pages'!D:D,"Page") -> 29
A37: Section / tool pages | B37: =COUNTIF('Site Pages'!A:A,"Section / Tool") -> 5
A38: Static pages | B38: =COUNTIF('Site Pages'!A:A,"Static") -> 9
A39: Total pages | B39: =SUM(B35:B38) -> 53
A40: Grand total URLs | B40: =B34+B39 -> 330

Sheet Site Pages
A1: Type | B1: Page | C1: URL Slug | D1: WP Type | E1: Status | F1: Notes
A2: Hub | B2: Animal Puns | C2: /animal-puns/ | D2: Page | E2: New | F2: Lists all 7 sub-hubs; mega-menu entry
A3: Sub-hub | B3: Pet Puns | C3: /pet-puns/ | D3: Page | E3: New | F3: Links to its 6 topic posts
A4: Sub-hub | B4: Farm Animal Puns | C4: /farm-animal-puns/ | D4: Page | E4: New | F4: Links to its 10 topic posts
A5: Sub-hub | B5: Wild Animal Puns | C5: /wild-animal-puns/ | D5: Page | E5: New | F5: Links to its 14 topic posts
A6: Sub-hub | B6: Bird Puns | C6: /bird-puns/ | D6: Page | E6: New | F6: Links to its 4 topic posts
A7: Sub-hub | B7: Sea Creature Puns | C7: /sea-creature-puns/ | D7: Page | E7: New | F7: Links to its 9 topic posts
A8: Sub-hub | B8: Insect & Bug Puns | C8: /insect-and-bug-puns/ | D8: Page | E8: New | F8: Links to its 6 topic posts
A9: Sub-hub | B9: Reptile & Amphibian Puns | C9: /reptile-and-amphibian-puns/ | D9: Page | E9: New | F9: Links to its 5 topic posts
A10: Hub | B10: Food & Drink Puns | C10: /food-and-drink-puns/ | D10: Page | E10: New | F10: Lists all 5 sub-hubs; mega-menu entry
A11: Sub-hub | B11: Fruit Puns | C11: /fruit-puns/ | D11: Page | E11: New | F11: Links to its 12 topic posts
A12: Sub-hub | B12: Vegetable Puns | C12: /vegetable-puns/ | D12: Page | E12: New | F12: Links to its 8 topic posts
... A62: Static | B62: DMCA | C62: /dmca/ | D62: Page | E62: Recommended | F62: Footer link

Sheet Header & Footer
A1: Site Header & Footer
A2: Slugs match the Topical Map / Site Pages tabs. Update here first if a slug changes.
A4: HEADER
A5: Label | B5: Type | C5: Slug | D5: Notes
A6: Puns | B6: mega menu | D6: Top-level nav item; opens mega menu
A7: ↳ By Topic | B7: sub-heading | D7: Lists the 10 hubs below
A8: ↳ Animal Puns | B8: link | C8: /animal-puns/ | D8: Hub page
A9: ↳ Food & Drink Puns | B9: link | C9: /food-and-drink-puns/ | D9: Hub page
A10: ↳ Nature & Science Puns | B10: link | C10: /nature-and-science-puns/ | D10: Hub page
A11: ↳ Holiday & Event Puns | B11: link | C11: /holiday-and-event-puns/ | D11: Hub page
A12: ↳ People & Relationship Puns | B12: link | C12: /people-and-relationship-puns/ | D12: Hub page
A13: ↳ Object & Everyday Puns | B13: link | C13: /object-and-everyday-puns/ | D13: Hub page
A14: ↳ Sport & Hobby Puns | B14: link | C14: /sport-and-hobby-puns/ | D14: Hub page
A15: ↳ Work & School Puns | B15: link | C15: /work-and-school-puns/ | D15: Hub page
A16: ↳ Fantasy & Pop Culture Puns | B16: link | C16: /fantasy-and-pop-culture-puns/ | D16: Hub page
A17: ↳ Word & Name Puns | B17: link | C17: /word-and-name-puns/ | D17: Hub page
A18: ↳ By Use | B18: sub-heading | D18: Lists the top use hubs
A19: ↳ Puns for Instagram Captions | B19: link | C19: /puns-for-instagram-captions/ | D19: Use hub
A20: ↳ Puns for Kids | B20: link | C20: /puns-for-kids/ | D20: Use hub
A21: ↳ Love Puns | B21: link | C21: /love-puns/ | D21: Use hub
A22: ↳ Dad Joke Puns | B22: link | C22: /dad-joke-puns/ | D22: Use hub
A23: ↳ Best Puns of All Time | B23: link | C23: /best-puns/ | D23: Use hub
A24: ↳ Learn | B24: sub-heading | D24: Outer section
A25: ↳ What Is a Pun? | B25: link | C25: /what-is-a-pun/ | D25: Outer page
A26: ↳ Types of Puns | B26: link | C26: /types-of-puns/ | D26: Outer page
A27: Riddles | B27: link | C27: /riddles/ | D27: Existing section
A28: Meanings | B28: link | C28: /meanings/ | D28: Existing section
A29: Pun Generator | B29: button | C29: /pun-generator/ | D29: Styled apart from the rest; right side of nav
A32: FOOTER
A33: Column / Zone | B33: Label | C33: Type | D33: Slug | E33: Notes
A34: Brand | B34: Logo | C34: logo | E34: Links to homepage
A35: Brand | B35: Tagline | C35: text | E35: "Crafty Puns is a wordplay library of original puns, riddles, and a free Pun Generator."
A36: Brand | B36: Pinterest | C36: social | D36: https://www.pinterest.com/craftypuns/ | E36: Existing account
A37: Brand | B37: Facebook | C37: social | E37: Add if active
A38: Brand | B38: Instagram | C38: social | E38: Add if active
A39: Popular Hubs | B39: Animal Puns | C39: link | D39: /animal-puns/
A40: Popular Hubs | B40: Food & Drink Puns | C40: link | D40: /food-and-drink-puns/
A41: Popular Hubs | B41: Holiday & Event Puns | C41: link | D41: /holiday-and-event-puns/
A42: Popular Hubs | B42: People & Relationship Puns | C42: link | D42: /people-and-relationship-puns/
A43: Popular Hubs | B43: Puns for Instagram Captions | C43: link | D43: /puns-for-instagram-captions/
...

Sheet Topical Map
A1: # | B1: Hub | C1: Sub-hub | D1: Page | E1: Target Query | F1: URL Slug | G1: Section | H1: Priority | I1: Seasonality | J1: Status on craftypuns.net | K1: Contextual Bridges | L1: Notes | M1: H1 Title | N1: Meta Title | O1: Title Length | P1: Meta Description | Q1: Desc Length
A2: 1 | B2: Animal Puns | C2: Pet Puns | D2: Cat Puns | E2: cat puns | F2: /cat-puns/ | G2: Core | H2: P1 | I2: Evergreen | J2: Not verified | K2: Up: Pet Puns → Animal Puns | Across: Dog Puns, Rabbit Puns | M2: 200+ Cat Puns That Are Purr-fectly Funny | N2: 200+ Cat Puns: One-Liners, Captions & Jokes | O2: =LEN(N2) -> 43 | P2: Laugh with 200+ cat puns: one-liners, Instagram captions, love and kids puns, plus cat jokes. Copy a favorite or make your own with our Pun Generator. | Q2: =LEN(P2) -> 150
A3: 2 | B3: Animal Puns | C3: Pet Puns | D3: Dog Puns | E3: dog puns | F3: /dog-puns/ | G3: Core | H3: P1 | I3: Evergreen | J3: Not verified | K3: Up: Pet Puns → Animal Puns | Across: Cat Puns, Rabbit Puns | M3: 200+ Dog Puns That Are Paw-sitively Hilarious | N3: 200+ Dog Puns: One-Liners, Captions & Jokes | O3: =LEN(N3) -> 43 | P3: Laugh with 200+ dog puns: one-liners, Instagram captions, love and kids puns, plus dog jokes. Copy a favorite or make your own with our Pun Generator. | Q3: =LEN(P3) -> 150
A4: 3 | B4: Animal Puns | C4: Pet Puns | D4: Rabbit Puns | E4: rabbit puns | F4: /rabbit-puns/ | G4: Core | H4: P2 | I4: Easter | J4: Live (verified) | K4: Up: Pet Puns → Animal Puns | Across: Cat Puns, Dog Puns | Seasonal: Easter hub | L4: Use one page for Rabbit/Bunny; Bunny as alias. | M4: 150+ Rabbit Puns That Are Hare-larious | N4: 150+ Rabbit Puns: One-Liners, Captions & Jokes | O4: =LEN(N4) -> 46 | P4: 150+ rabbit puns: one-liners, Instagram captions, love and kids puns. Copy a favorite or make your own with our free Pun Generator. | Q4: =LEN(P4) -> 131
A5: 4 | B5: Animal Puns | C5: Pet Puns | D5: Hamster Puns | E5: hamster puns | F5: /hamster-puns/ | G5: Core | H5: P3 | I5: Evergreen | J5: Not verified | K5: Up: Pet Puns → Animal Puns | Across: Cat Puns, Dog Puns | M5: 100+ Hamster Puns That Keep the Wheel Spinning | N5: 100+ Hamster Puns: One-Liners, Captions & Jokes | O5: =LEN(N5) -> 47 | P5: 100+ hamster puns: one-liners, Instagram captions, love and kids puns. Copy a favorite or make your own with our free Pun Generator. | Q5: =LEN(P5) -> 132
A6: 5 | B6: Animal Puns | C6: Pet Puns | D6: Parrot Puns | E6: parrot puns | F6: /parrot-puns/ | G6: Core | H6: P3 | I6: Evergreen | J6: Not verified | K6: Up: Pet Puns → Animal Puns | Across: Cat Puns, Dog Puns | M6: 100+ Parrot Puns Worth Repeating | N6: 100+ Parrot Puns: One-Liners, Captions & Jokes | O6: =LEN(N6) -> 46 | P6: 100+ parrot puns: one-liners, Instagram captions, love and kids puns. Copy a favorite or make your own with our free Pun Generator. | Q6: =LEN(P6) -> 131
A7: 6 | B7: Animal Puns | C7: Pet Puns | D7: Goldfish Puns | E7: goldfish puns | F7: /goldfish-puns/ | G7: Core | H7: P3 | I7: Evergreen | J7: Not verified | K7: Up: Pet Puns → Animal Puns | Across: Cat Puns, Dog Puns | M7: 100+ Goldfish Puns That Are Pure Gold | N7: 100+ Goldfish Puns: One-Liners, Captions & Jokes | O7: =LEN(N7) -> 48 | P7: 100+ goldfish puns: one-liners, Instagram captions, love and kids puns. Copy a favorite or make your own with our free Pun Generator. | Q7: =LEN(P7) -> 133
A8: 7 | B8: Animal Puns | C8: Farm Animal Puns | D8: Cow Puns | E8: cow puns | F8: /cow-puns/ | G8: Core | H8: P2 | I8: Evergreen | J8: Not verified | K8: Up: Farm Animal Puns → Animal Puns | Across: Pig Puns, Chicken Puns | M8: 150+ Cow Puns That Are Udderly Hilarious | N8: 150+ Cow Puns: One-Liners, Captions & Jokes | O8: =LEN(N8) -> 43 | P8: Laugh with 150+ cow puns: one-liners, Instagram captions, love and kids puns, plus cow jokes. Copy a favorite or make your own with our Pun Generator. | Q8: =LEN(P8) -> 150
A9: 8 | B9: Animal Puns | C9: Farm Animal Puns | D9: Pig Puns | E9: pig puns | F9: /pig-puns/ | G9: Core | H9: P2 | I9: Evergreen | J9: Not verified | K9: Up: Farm Animal Puns → Animal Puns | Across: Cow Puns, Chicken Puns | M9: 150+ Pig Puns That Are Hog-Wild Funny | N9: 150+ Pig Puns: One-Liners, Captions & Jokes | O9: =LEN(N9) -> 43 | P9: Laugh with 150+ pig puns: one-liners, Instagram captions, love and kids puns, plus pig jokes. Copy a favorite or make your own with our Pun Generator. | Q9: =LEN(P9) -> 150
A10: 9 | B10: Animal Puns | C10: Farm Animal Puns | D10: Chicken Puns | E10: chicken puns | F10: /chicken-puns/ | G10: Core | H10: P2 | I10: Evergreen | J10: Not verified | K10: Up: Farm Animal Puns → Animal Puns | Across: Cow Puns, Pig Puns | M10: 150+ Chicken Puns That Are Egg-stra Funny | N10: 150+ Chicken Puns: One-Liners, Captions & Jokes | O10: =LEN(N10) -> 47 | P10: 150+ chicken puns: one-liners, Instagram captions, love and kids puns. Copy a favorite or make your own with our free Pun Generator. | Q10: =LEN(P10) -> 132
A11: 10 | B11: Animal Puns | C11: Farm Animal Puns | D11: Sheep Puns | E11: sheep puns | F11: /sheep-puns/ | G11: Core | H11: P2 | I11: Evergreen | J11: Not verified | K11: Up: Farm Animal Puns → Animal Puns | Across: Cow Puns, Pig Puns | M11: 150+ Sheep Puns That Are Shear Genius | N11: 150+ Sheep Puns: One-Liners, Captions & Jokes | O11: =LEN(N11) -> 45 | P11: Laugh with 150+ sheep puns: one-liners, Instagram captions, love and kids puns, plus sheep jokes. Copy a favorite or make your own with our Pun Generator. | Q11: =LEN(P11) -> 154
A12: 11 | B12: Animal Puns | C12: Farm Animal Puns | D12: Goat Puns | E12: goat puns | F12: /goat-puns/ | G12: Core | H12: P2 | I12: Evergreen | J12: Not verified | K12: Up: Farm Animal Puns → Animal Puns | Across: Cow Puns, Pig Puns | M12: 150+ Goat Puns That Are the G.O.A.T. | N12: 150+ Goat Puns: One-Liners, Captions & Jokes | O12: =LEN(N12) -> 44 | P12: Laugh with 150+ goat puns: one-liners, Instagram captions, love and kids puns, plus goat jokes. Copy a favorite or make your own with our Pun Generator. | Q12: =LEN(P12) -> 152
A13: 12 | B13: Animal Puns | C13: Farm Animal Puns | D13: Horse Puns | E13: horse puns | F13: /horse-puns/ | G13: Core | H13: P2 | I13: Evergreen | J13: Not verified | K13: Up: Farm Animal Puns → Animal Puns | Across: Cow Puns, Pig Puns | M13: 150+ Horse Puns That Are Unbridled Fun | N13: 150+ Horse Puns: One-Liners, Captions & Jokes | O13: =LEN(N13) -> 45 | P13: Laugh with 150+ horse puns: one-liners, Instagram captions, love and kids puns, plus horse jokes. Copy a favorite or make your own with our Pun Generator. | Q13: =LEN(P13) -> 154
A14: 13 | B14: Animal Puns | C14: Farm Animal Puns | D14: Llama Puns | E14: llama puns | F14: /llama-puns/ | G14: Core | H14: P2 | I14: Evergreen | J14: Not verified | K14: Up: Farm Animal Puns → Animal Puns | Across: Cow Puns, Pig Puns | M14: 150+ Llama Puns That Are Llama-zing | N14: 150+ Llama Puns: One-Liners, Captions & Jokes | O14: =LEN(N14) -> 45 | P14: Laugh with 150+ llama puns: one-liners, Instagram captions, love and kids puns, plus llama jokes. Copy a favorite or make your own with our Pun Generator. | Q14: =LEN(P14) -> 154
A15: 14 | B15: Animal Puns | C15: Farm Animal Puns | D15: Duck Puns | E15: duck puns | F15: /duck-puns/ | G15: Core | H15: P2 | I15: Evergreen | J15: Live (verified) | K15: Up: Farm Animal Puns → Animal Puns | Across: Cow Puns, Pig Puns | M15: 150+ Duck Puns That Are Totally Quackers | N15: 150+ Duck Puns: One-Liners, Captions & Jokes | O15: =LEN(N15) -> 44 | P15: Laugh with 150+ duck puns: one-liners, Instagram captions, love and kids puns, plus duck jokes. Copy a favorite or make your own with our Pun Generator. | Q15: =LEN(P15) -> 152
A16: 15 | B16: Animal Puns | C16: Farm Animal Puns | D16: Goose Puns | E16: goose puns | F16: /goose-puns/ | G16: Core | H16: P3 | I16: Evergreen | J16: Live (verified) | K16: Up: Farm Animal Puns → Animal Puns | Across: Cow Puns, Pig Puns | M16: 100+ Goose Puns Worth Honking About | N16: 100+ Goose Puns: One-Liners, Captions & Jokes | O16: =LEN(N16) -> 45 | P16: Laugh with 100+ goose puns: one-liners, Instagram captions, love and kids puns, plus goose jokes. Copy a favorite or make your own with our Pun Generator. | Q16: =LEN(P16) -> 154
... A44: 43 | B44: Animal Puns | C44: Sea Creature Puns | D44: Squid Puns | E44: squid puns | F44: /squid-puns/ | G44: Core | H44: P3 | I44: Evergreen | J44: Not verified | K44: Up: Sea Creature Puns → Animal Puns | Across: Fish Puns, Shark Puns | M44: 100+ Squid Puns That Are Squid-diculous | N44: 100+ Squid Puns: One-Liners, Captions & Jokes | O44: =LEN(N44) -> 45 | P44: Laugh with 100+ squid puns: one-liners, Instagram captions, love and kids puns, plus squid jokes. Copy a favorite or make your own with our Pun Generator. | Q44: =LEN(P44) -> 154
A45: 44 | B45: Animal Puns | C45: Insect & Bug Puns | D45: Bee Puns | E45: bee puns | F45: /bee-puns/ | G45: Core | H45: P2 | I45: Evergreen | J45: Live (verified) | K45: Up: Insect & Bug Puns → Animal Puns | Across: Butterfly Puns, Ant Puns | L45: Live page is thin (46 items); expand. | M45: 150+ Bee Puns Worth Buzzing About | N45: 150+ Bee Puns: One-Liners, Captions & Jokes | O45: =LEN(N45) -> 43 | P45: Laugh with 150+ bee puns: one-liners, Instagram captions, love and kids puns, plus bee jokes. Copy a favorite or make your own with our Pun Generator. | Q45: =LEN(P45) -> 150
A46: 45 | B46: Animal Puns | C46: Insect & Bug Puns | D46: Butterfly Puns | E46: butterfly puns | F46: /butterfly-puns/ | G46: Core | H46: P3 | I46: Spring | J46: Not verified | K46: Up: Insect & Bug Puns → Animal Puns | Across: Bee Puns, Ant Puns | Seasonal: Spring hub | M46: 100+ Butterfly Puns That Will Give You Butterflies | N46: 100+ Butterfly Puns: One-Liners, Captions & Jokes | O46: =LEN(N46) -> 49 | P46: 100+ butterfly puns: one-liners, Instagram captions, love and kids puns. Copy a favorite or make your own with our free Pun Generator. | Q46: =LEN(P46) -> 134
A47: 46 | B47: Animal Puns | C47: Insect & Bug Puns | D47: Ant Puns | E47: ant puns | F47: /ant-puns/ | G47: Core | H47: P3 | I47: Evergreen | J47: Not verified | K47: Up: Insect & Bug Puns → Animal Puns | Across: Bee Puns, Butterfly Puns | M47: 100+ Ant Puns That Are Ant-stoppable | N47: 100+ Ant Puns: One-Liners, Captions & Jokes | O47: =LEN(N47) -> 43 | P47: Laugh with 100+ ant puns: one-liners, Instagram captions, love and kids puns, plus ant jokes. Copy a favorite or make your own with our Pun Generator. | Q47: =LEN(P47) -> 150
A48: 47 | B48: Animal Puns | C48: Insect & Bug Puns | D48: Spider Puns | E48: spider puns | F48: /spider-puns/ | G48: Core | H48: P3 | I48: Halloween | J48: Not verified | K48: Up: Insect & Bug Puns → Animal Puns | Across: Bee Puns, Butterfly Puns | Seasonal: Halloween hub | M48: 100+ Spider Puns That Are Web-tastic | N48: 100+ Spider Puns: One-Liners, Captions & Jokes | O48: =LEN(N48) -> 46 | P48: 100+ spider puns: one-liners, Instagram captions, love and kids puns. Copy a favorite or make your own with our free Pun Generator. | Q48: =LEN(P48) -> 131
A49: 48 | B49: Animal Puns | C49: Insect & Bug Puns | D49: Snail Puns | E49: snail puns | F49: /snail-puns/ | G49: Core | H49: P3 | I49: Evergreen | J49: Not verified | K49: Up: Insect & Bug Puns → Animal Puns | Across: Bee Puns, Butterfly Puns | M49: 100+ Snail Puns Out of Their Shell | N49: 100+ Snail Puns: One-Liners, Captions & Jokes | O49: =LEN(N49) -> 45 | P49: Laugh with 100+ snail puns: one-liners, Instagram captions, love and kids puns, plus snail jokes. Copy a favorite or make your own with our Pun Generator. | Q49: =LEN(P49) -> 154
A50: 49 | B50: Animal Puns | C50: Insect & Bug Puns | D50: Ladybug Puns | E50: ladybug puns | F50: /ladybug-puns/ | G50: Core | H50: P3 | I50: Evergreen | J50: Not verified | K50: Up: Insect & Bug Puns → Animal Puns | Across: Bee Puns, Butterfly Puns | M50: 100+ Ladybug Puns That Are Spot-On | N50: 100+ Ladybug Puns: One-Liners, Captions & Jokes | O50: =LEN(N50) -> 47 | P50: 100+ ladybug puns: one-liners, Instagram captions, love and kids puns. Copy a favorite or make your own with our free Pun Generator. | Q50: =LEN(P50) -> 132
A51: 50 | B51: Animal Puns | C51: Reptile & Amphibian Puns | D51: Frog Puns | E51: frog puns | F51: /frog-puns/ | G51: Core | H51: P2 | I51: Evergreen | J51: Not verified | K51: Up: Reptile & Amphibian Puns → Animal Puns | Across: Snake Puns, Dinosaur Puns | M51: 150+ Frog Puns That Are Toad-ally Hilarious | N51: 150+ Frog Puns: One-Liners, Captions & Jokes | O51: =LEN(N51) -> 44 | P51: Laugh with 150+ frog puns: one-liners, Instagram captions, love and kids puns, plus frog jokes. Copy a favorite or make your own with our Pun Generator. | Q51: =LEN(P51) -> 152
A52: 51 | B52: Animal Puns | C52: Reptile & Amphibian Puns | D52: Snake Puns | E52: snake puns | F52: /snake-puns/ | G52: Core | H52: P2 | I52: Evergreen | J52: Not verified | K52: Up: Reptile & Amphibian Puns → Animal Puns | Across: Frog Puns, Dinosaur Puns | M52: 150+ Snake Puns That Are Hiss-terical | N52: 150+ Snake Puns: One-Liners, Captions & Jokes | O52: =LEN(N52) -> 45 | P52: Laugh with 150+ snake puns: one-liners, Instagram captions, love and kids puns, plus snake jokes. Copy a favorite or make your own with our Pun Generator. | Q52: =LEN(P52) -> 154
A53: 52 | B53: Animal Puns | C53: Reptile & Amphibian Puns | D53: Dinosaur Puns | E53: dinosaur puns | F53: /dinosaur-puns/ | G53: Core | H53: P2 | I53: Evergreen | J53: Not verified | K53: Up: Reptile & Amphibian Puns → Animal Puns | Across: Frog Puns, Snake Puns | M53: 150+ Dinosaur Puns That Are Dino-mite | N53: 150+ Dinosaur Puns: One-Liners, Captions & Jokes | O53: =LEN(N53) -> 48 | P53: 150+ dinosaur puns: one-liners, Instagram captions, love and kids puns. Copy a favorite or make your own with our free Pun Generator. | Q53: =LEN(P53) -> 133
A54: 53 | B54: Animal Puns | C54: Reptile & Amphibian Puns | D54: Lizard Puns | E54: lizard puns | F54: /lizard-puns/ | G54: Core | H54: P3 | I54: Evergreen | J54: Not verified | K54: Up: Reptile & Amphibian Puns → Animal Puns | Across: Frog Puns, Snake Puns | M54: 100+ Lizard Puns That Are Scale-tastic | N54: 100+ Lizard Puns: One-Liners, Captions & Jokes | O54: =LEN(N54) -> 46 | P54: 100+ lizard puns: one-liners, Instagram captions, love and kids puns. Copy a favorite or make your own with our free Pun Generator. | Q54: =LEN(P54) -> 131
A55: 54 | B55: Animal Puns | C55: Reptile & Amphibian Puns | D55: Alligator Puns | E55: alligator puns | F55: /alligator-puns/ | G55: Core | H55: P3 | I55: Evergreen | J55: Not verified | K55: Up: Reptile & Amphibian Puns → Animal Puns | Across: Frog Puns, Snake Puns | M55: 100+ Alligator Puns to Share Later, Alligator | N55: 100+ Alligator Puns: One-Liners, Captions & Jokes | O55: =LEN(N55) -> 49 | P55: 100+ alligator puns: one-liners, Instagram captions, love and kids puns. Copy a favorite or make your own with our free Pun Generator. | Q55: =LEN(P55) -> 134
A56: 55 | B56: Food & Drink Puns | C56: Fruit Puns | D56: Apple Puns | E56: apple puns | F56: /apple-puns/ | G56: Core | H56: P2 | I56: Fall | J56: Not verified | K56: Up: Fruit Puns → Food & Drink Puns | Across: Banana Puns, Orange Puns | Seasonal: Fall hub | M56: 150+ Apple Puns That Are Funny to the Core | N56: 150+ Apple Puns: One-Liners, Captions & Jokes | O56: =LEN(N56) -> 45 | P56: Laugh with 150+ apple puns: one-liners, Instagram captions, love and kids puns, plus apple jokes. Copy a favorite or make your own with our Pun Generator. | Q56: =LEN(P56) -> 154
A57: 56 | B57: Food & Drink Puns | C57: Fruit Puns | D57: Banana Puns | E57: banana puns | F57: /banana-puns/ | G57: Core | H57: P2 | I57: Evergreen | J57: Not verified | K57: Up: Fruit Puns → Food & Drink Puns | Across: Apple Puns, Orange Puns | M57: 150+ Banana Puns That Will Drive You Bananas | N57: 150+ Banana Puns: One-Liners, Captions & Jokes | O57: =LEN(N57) -> 46 | P57: 150+ banana puns: one-liners, Instagram captions, love and kids puns. Copy a favorite or make your own with our free Pun Generator. | Q57: =LEN(P57) -> 131
... A69: 68 | B69: Food & Drink Puns | C69: Vegetable Puns | D69: Corn Puns | E69: corn puns | F69: /corn-puns/ | G69: Core | H69: P2 | I69: Fall | J69: Live (verified) | K69: Up: Vegetable Puns → Food & Drink Puns | Across: Potato Puns, Pumpkin Puns | Seasonal: Fall hub | M69: 150+ Corn Puns That Are A-maize-ing | N69: 150+ Corn Puns: One-Liners, Captions & Jokes | O69: =LEN(N69) -> 44 | P69: Laugh with 150+ corn puns: one-liners, Instagram captions, love and kids puns, plus corn jokes. Copy a favorite or make your own with our Pun Generator. | Q69: =LEN(P69) -> 152
A70: 69 | B70: Food & Drink Puns | C70: Vegetable Puns | D70: Pumpkin Puns | E70: pumpkin puns | F70: /pumpkin-puns/ | G70: Core | H70: P2 | I70: Halloween | J70: Not verified | K70: Up: Vegetable Puns → Food & Drink Puns | Across: Potato Puns, Corn Puns | Seasonal: Halloween hub | L70: Seasonal; also bridge to Vegetable Puns. | M70: 150+ Pumpkin Puns That Are Gourd-geous | N70: 150+ Pumpkin Puns: One-Liners, Captions & Jokes | O70: =LEN(N70) -> 47 | P70: 150+ pumpkin puns: one-liners, Instagram captions, love and kids puns. Copy a favorite or make your own with our free Pun Generator. | Q70: =LEN(P70) -> 132
A71: 70 | B71: Food & Drink Puns | C71: Vegetable Puns | D71: Carrot Puns | E71: carrot puns | F71: /carrot-puns/ | G71: Core | H71: P3 | I71: Evergreen | J71: Not verified | K71: Up: Vegetable Puns → Food & Drink Puns | Across: Potato Puns, Corn Puns | M71: 100+ Carrot Puns Rooted in Fun | N71: 100+ Carrot Puns: One-Liners, Captions & Jokes | O71: =LEN(N71) -> 46 | P71: 100+ carrot puns: one-liners, Instagram captions, love and kids puns. Copy a favorite or make your own with our free Pun Generator. | Q71: =LEN(P71) -> 131
A72: 71 | B72: Food & Drink Puns | C72: Vegetable Puns | D72: Pea Puns | E72: pea puns | F72: /pea-puns/ | G72: Core | H72: P3 | I72: Evergreen | J72: Not verified | K72: Up: Vegetable Puns → Food & Drink Puns | Across: Potato Puns, Corn Puns | M72: 100+ Pea Puns to Give Peas a Chance | N72: 100+ Pea Puns: One-Liners, Captions & Jokes | O72: =LEN(N72) -> 43 | P72: Laugh with 100+ pea puns: one-liners, Instagram captions, love and kids puns, plus pea jokes. Copy a favorite or make your own with our Pun Generator. | Q72: =LEN(P72) -> 150
A73: 72 | B73: Food & Drink Puns | C73: Vegetable Puns | D73: Onion Puns | E73: onion puns | F73: /onion-puns/ | G73: Core | H73: P3 | I73: Evergreen | J73: Not verified | K73: Up: Vegetable Puns → Food & Drink Puns | Across: Potato Puns, Corn Puns | M73: 100+ Onion Puns That Will Make You Cry Laughing | N73: 100+ Onion Puns: One-Liners, Captions & Jokes | O73: =LEN(N73) -> 45 | P73: Laugh with 100+ onion puns: one-liners, Instagram captions, love and kids puns, plus onion jokes. Copy a favorite or make your own with our Pun Generator. | Q73: =LEN(P73) -> 154
A74: 73 | B74: Food & Drink Puns | C74: Vegetable Puns | D74: Pepper Puns | E74: pepper puns | F74: /pepper-puns/ | G74: Core | H74: P3 | I74: Evergreen | J74: Not verified | K74: Up: Vegetable Puns → Food & Drink Puns | Across: Potato Puns, Corn Puns | M74: 100+ Pepper Puns That Bring the Heat | N74: 100+ Pepper Puns: One-Liners, Captions & Jokes | O74: =LEN(N74) -> 46 | P74: 100+ pepper puns: one-liners, Instagram captions, love and kids puns. Copy a favorite or make your own with our free Pun Generator. | Q74: =LEN(P74) -> 131
A75: 74 | B75: Food & Drink Puns | C75: Vegetable Puns | D75: Mushroom Puns | E75: mushroom puns | F75: /mushroom-puns/ | G75: Core | H75: P3 | I75: Evergreen | J75: Not verified | K75: Up: Vegetable Puns → Food & Drink Puns | Across: Potato Puns, Corn Puns | M75: 100+ Mushroom Puns From a Real Fun-gi | N75: 100+ Mushroom Puns: One-Liners, Captions & Jokes | O75: =LEN(N75) -> 48 | P75: 100+ mushroom puns: one-liners, Instagram captions, love and kids puns. Copy a favorite or make your own with our free Pun Generator. | Q75: =LEN(P75) -> 133
A76: 75 | B76: Food & Drink Puns | C76: Dessert & Sweet Puns | D76: Ice Cream Puns | E76: ice cream puns | F76: /ice-cream-puns/ | G76: Core | H76: P1 | I76: Summer | J76: Not verified | K76: Up: Dessert & Sweet Puns → Food & Drink Puns | Across: Cake Puns, Cookie Puns | Seasonal: Summer hub | M76: 200+ Ice Cream Puns That Are Sundae-licious | N76: 200+ Ice Cream Puns: One-Liners, Captions & Jokes | O76: =LEN(N76) -> 49 | P76: 200+ ice cream puns: one-liners, Instagram captions, love and kids puns. Copy a favorite or make your own with our free Pun Generator. | Q76: =LEN(P76) -> 134
A77: 76 | B77: Food & Drink Puns | C77: Dessert & Sweet Puns | D77: Cake Puns | E77: cake puns | F77: /cake-puns/ | G77: Core | H77: P2 | I77: Birthday | J77: Not verified | K77: Up: Dessert & Sweet Puns → Food & Drink Puns | Across: Ice Cream Puns, Cookie Puns | Seasonal: Birthday hub | M77: 150+ Cake Puns That Are a Piece of Cake | N77: 150+ Cake Puns: One-Liners, Captions & Jokes | O77: =LEN(N77) -> 44 | P77: Laugh with 150+ cake puns: one-liners, Instagram captions, love and kids puns, plus cake jokes. Copy a favorite or make your own with our Pun Generator. | Q77: =LEN(P77) -> 152
A78: 77 | B78: Food & Drink Puns | C78: Dessert & Sweet Puns | D78: Cookie Puns | E78: cookie puns | F78: /cookie-puns/ | G78: Core | H78: P2 | I78: Christmas | J78: Not verified | K78: Up: Dessert & Sweet Puns → Food & Drink Puns | Across: Ice Cream Puns, Cake Puns | Seasonal: Christmas hub | M78: 150+ Cookie Puns That Are Crumb-tastic | N78: 150+ Cookie Puns: One-Liners, Captions & Jokes | O78: =LEN(N78) -> 46 | P78: 150+ cookie puns: one-liners, Instagram captions, love and kids puns. Copy a favorite or make your own with our free Pun Generator. | Q78: =LEN(P78) -> 131
...

Sheet Use Hubs
A1: Use Hub Page | B1: Target Query | C1: URL Slug | D1: Priority | E1: Pulls From / Links To | F1: Format Rule | G1: H1 Title | H1: Meta Title | I1: Title Length | J1: Meta Description | K1: Desc Length
A2: Puns for Instagram Captions | B2: puns for instagram captions | C2: /puns-for-instagram-captions/ | D2: P1 | E2: Every topic page's 'Captions' H2 | F2: Short, standalone, under ~8 words | G2: 200+ Puns for Instagram Captions That Get the Likes Rolling | H2: 200+ Puns for Instagram Captions (Short, Funny & Cute) | I2: =LEN(H2) -> 54 | J2: Find 200+ puns for Instagram captions by topic: food, animals, travel, holidays and more. Short, funny and cute lines ready to copy and post. | K2: =LEN(J2) -> 141
A3: Puns for Kids | B3: puns for kids | C3: /puns-for-kids/ | D3: P1 | E3: Every topic page's 'For Kids' H2 | F3: Clean, simple words; Q&A format | G3: 200+ Puns for Kids That Are Clean, Silly and Fun | H3: 200+ Puns for Kids: Clean, Silly Jokes They'll Love | I3: =LEN(H3) -> 51 | J3: Clean puns for kids: animal, food, school and holiday wordplay with easy jokes. Great for lunchbox notes, classrooms and family game night. | K3: =LEN(J3) -> 139
A4: Love Puns | B4: love puns | C4: /love-puns/ | D4: P1 | E4: Every 'Love' H2; Valentine's Day Puns, Couple Puns | F4: Second person ('you'); sweet tone | G4: 200+ Love Puns That Will Steal Your Heart | H4: 200+ Love Puns: Cute, Flirty & Romantic Wordplay | I4: =LEN(H4) -> 48 | J4: Cute and flirty love puns for texts, cards and captions, from sweet food puns to animal valentines. Find the perfect line to make someone smile. | K4: =LEN(J4) -> 144
A5: Pickup Line Puns | B5: pun pickup lines | C5: /pun-pickup-lines/ | D5: P2 | E5: Every 'Pickup Lines' H2 | F5: Flirty, clean, one sentence | G5: 150+ Pun Pickup Lines That Are Cheesy in the Best Way | H5: 150+ Pun Pickup Lines: Cheesy, Clean & Flirty | I5: =LEN(H5) -> 45 | J5: Clean, cheesy pun pickup lines for every topic, from food and animals to science and space. Perfect for flirty texts, cards and breaking the ice. | K5: =LEN(J5) -> 145
A6: Funny Puns | B6: funny puns | C6: /funny-puns/ | D6: P1 | E6: Best-of from all topic pages | F6: Strongest lines only | G6: 300+ Funny Puns That Will Make You Groan and Grin | H6: 300+ Funny Puns: The Best Wordplay by Topic | I6: =LEN(H6) -> 43 | J6: The funniest puns on Crafty Puns, hand-picked from every topic: animals, food, holidays, science and more. One-liners and jokes you can copy instantly. | K6: =LEN(J6) -> 151
A7: Short Puns | B7: short puns | C7: /short-puns/ | D7: P2 | E7: Every 'Short' H2 | F7: 1-5 words | G7: 200+ Short Puns That Pack a Punch | H7: 200+ Short Puns: Quick One-Word & One-Line Wordplay | I7: =LEN(H7) -> 51 | J7: Short puns of one to five words for captions, bios, texts and signs. Quick, clever wordplay sorted by topic and ready to copy. | K7: =LEN(J7) -> 126
A8: One-Liner Puns | B8: one liner puns | C8: /one-liner-puns/ | D8: P2 | E8: Every 'One-Liners' H2 | F8: Single sentence, twist at end | G8: 250+ One-Liner Puns With a Twist at the End | H8: 250+ One-Liner Puns: Quick, Clever & Funny | I8: =LEN(H8) -> 42 | J8: One-liner puns that land in a single sentence. Clever wordplay on animals, food, work, school and more, ready for chats, captions and cards. | K8: =LEN(J8) -> 140
A9: Bad & Cheesy Puns | B9: bad puns | C9: /bad-puns/ | D9: P2 | E9: Dad Joke Puns; Puns About Puns | F9: Groan-worthy on purpose | G9: 150+ Bad Puns So Cheesy They're Grate | H9: 150+ Bad Puns So Cheesy They're Actually Good | I9: =LEN(H9) -> 45 | J9: Groan-worthy bad puns and cheesy wordplay, collected for maximum eye-rolls. Perfect for dad jokes, office chats and teasing your friends. | K9: =LEN(J9) -> 137
A10: Dad Joke Puns | B10: dad joke puns | C10: /dad-joke-puns/ | D10: P1 | E10: Father's Day Puns; Bad Puns | F10: Setup + groaner punchline | G10: 200+ Dad Joke Puns That Are Groan-tastic | H10: 200+ Dad Joke Puns: Corny, Clean & Groan-Worthy | I10: =LEN(H10) -> 47 | J10: Dad joke puns with corny setups and groaner punchlines. Clean, family-friendly wordplay for Father's Day, road trips and dinner-table laughs. | K10: =LEN(J10) -> 141
A11: Clean Puns | B11: clean puns | C11: /clean-puns/ | D11: P2 | E11: Puns for Kids; Work & Office Puns | F11: Workplace/classroom safe | G11: 200+ Clean Puns Safe for Work, School and Family | H11: 200+ Clean Puns for Work, School & Kids | I11: =LEN(H11) -> 39 | J11: Clean puns safe for the office, classroom and family chats. Friendly wordplay on food, animals, science and holidays, all ready to copy. | K11: =LEN(J11) -> 136
A12: Puns for Teachers | B12: puns for teachers | C12: /puns-for-teachers/ | D12: P2 | E12: School, Teacher, Science, Math Puns | F12: Classroom + bulletin-board use | G12: 150+ Puns for Teachers That Are Top of the Class | H12: 150+ Puns for Teachers: Classroom & Bulletin Boards | I12: =LEN(H12) -> 51 | J12: Puns for teachers and classrooms: science, math, reading and school wordplay for bulletin boards, lesson openers and teacher appreciation cards. | K12: =LEN(J12) -> 144
A13: Puns for Cards | B13: puns for cards | C13: /puns-for-cards/ | D13: P2 | E13: Birthday, Christmas, Valentine's hubs | F13: Card-length, warm | G13: 200+ Puns for Cards That Say It With a Smile | H13: 200+ Puns for Cards: Birthday, Holiday & Love | I13: =LEN(H13) -> 45 | J13: Card-ready puns for birthdays, Christmas, Valentine's Day, thank-yous and more. Short, warm wordplay that fits inside any greeting card. | K13: =LEN(J13) -> 136
A14: Best Puns of All Time | B14: best puns | C14: /best-puns/ | D14: P1 | E14: Outer: What Is a Pun; all hubs | F14: Curated flagship list; strong link target | G14: The 100 Best Puns of All Time | H14: The Best Puns of All Time: 100 Classic Wordplay Gems | I14: =LEN(H14) -> 52 | J14: The best puns of all time, from classic wordplay to modern one-liners, with what makes each one work. Find your favorite and share the groan. | K14: =LEN(J14) -> 141

Sheet Outer Section
A1: Page (H1 draft) | B1: Target Query | C1: URL Slug | D1: Priority | E1: Angle / Bridge | F1: H1 Title | G1: Meta Title | H1: Title Length | I1: Meta Description | J1: Desc Length
A2: What Is a Pun? Definition, Meaning & Examples | B2: what is a pun | C2: /what-is-a-pun/ | D2: P1 | E2: Definition-first; links to Types of Puns + Pun Generator | F2: What Is a Pun? Definition, Types & Examples | G2: What Is a Pun? Meaning, Types & Examples | H2: =LEN(G2) -> 40 | I2: A pun is wordplay that uses a word's double meaning or a similar sound for humor. Learn the definition, main types of puns and easy examples. | J2: =LEN(I2) -> 141
A3: Types of Puns | B3: types of puns | C3: /types-of-puns/ | D3: P1 | E3: Hub for the 6 type pages below | F3: Types of Puns: 7 Kinds of Wordplay With Examples | G3: Types of Puns: 7 Kinds Explained With Examples | H3: =LEN(G3) -> 46 | I3: Learn the main types of puns, including homophonic, homographic, compound, recursive and visual puns, with clear examples of each. | J3: =LEN(I3) -> 130
A4: Homophonic Puns | B4: homophonic puns | C4: /homophonic-puns/ | D4: P2 | E4: Same/similar sound, different meaning | F4: What Are Homophonic Puns? Meaning & Examples | G4: Homophonic Puns: Meaning, How They Work & Examples | H4: =LEN(G4) -> 50 | I4: Homophonic puns use words that sound alike but mean different things. See how they work, why they land and examples you can use. | J4: =LEN(I4) -> 128
A5: Homographic Puns | B5: homographic puns | C5: /homographic-puns/ | D5: P2 | E5: Same spelling, different meaning | F5: What Are Homographic Puns? Meaning & Examples | G5: Homographic Puns: Meaning & Examples | H5: =LEN(G5) -> 36 | I5: Homographic puns play on words spelled the same but with different meanings. Learn how they work with simple, funny examples. | J5: =LEN(I5) -> 125
A6: Homonymic Puns | B6: homonymic puns | C6: /homonymic-puns/ | D6: P3 | E6: Combines homophonic + homographic | F6: What Are Homonymic Puns? Meaning & Examples | G6: Homonymic Puns: Meaning & Examples | H6: =LEN(G6) -> 34 | I6: Homonymic puns use words that sound and look the same but mean different things. Learn how they differ from other pun types, with examples. | J6: =LEN(I6) -> 139
A7: Compound Puns | B7: compound puns | C7: /compound-puns/ | D7: P3 | E7: Several puns in one sentence | F7: What Are Compound Puns? Meaning & Examples | G7: Compound Puns: Meaning & Examples | H7: =LEN(G7) -> 33 | I7: Compound puns pack two or more puns into one sentence. See how they are built and read examples that stack the wordplay. | J7: =LEN(I7) -> 120
A8: Recursive Puns | B8: recursive puns | C8: /recursive-puns/ | D8: P3 | E8: Second part depends on the first | F8: What Are Recursive Puns? Meaning & Examples | G8: Recursive Puns: Meaning & Examples | H8: =LEN(G8) -> 34 | I8: Recursive puns need the first part understood to get the second. Learn how this layered wordplay works, with examples. | J8: =LEN(I8) -> 118
A9: Visual Puns | B9: visual puns | C9: /visual-puns/ | D9: P2 | E9: Image-based; strong Pinterest asset | F9: What Are Visual Puns? Meaning & Examples | G9: Visual Puns: Meaning & Examples of Picture Wordplay | H9: =LEN(G9) -> 51 | I9: Visual puns use images instead of words to create a double meaning. Explore how they work in art, ads and memes, with examples. | J9: =LEN(I9) -> 127
A10: Texting Puns (Letters & Numbers) | B10: texting puns | C10: /texting-puns/ | D10: P3 | E10: Bridge to Meanings (slang) section | F10: What Are Texting Puns? Letter & Number Wordplay | G10: Texting Puns: Letter, Number & Spelling Wordplay | H10: =LEN(G10) -> 48 | I10: Texting puns use letters, numbers and short spellings, like 'gr8' or 'CU', for wordplay. See how they work, with examples. | J10: =LEN(I10) -> 122
A11: How to Write a Pun | B11: how to write a pun | C11: /how-to-write-a-pun/ | D11: P1 | E11: Step-by-step; ends with Pun Generator CTA | F11: How to Write a Pun in 5 Simple Steps | G11: How to Write a Pun: 5 Easy Steps With Examples | H11: =LEN(G11) -> 46 | I11: Learn how to write a pun step by step: pick a topic, build a word bank, find sound-alikes and test the line. Or try our free Pun Generator. | J11: =LEN(I11) -> 139
A12: Pun vs Joke vs Riddle | B12: pun vs joke | C12: /pun-vs-joke-vs-riddle/ | D12: P2 | E12: Bridge to Riddles section | F12: Pun vs Joke vs Riddle: What's the Difference? | G12: Pun vs Joke vs Riddle: What's the Difference? | H12: =LEN(G12) -> 45 | I12: Puns, jokes and riddles all aim for a laugh, but they work differently. Learn the difference between each, with side-by-side examples. | J12: =LEN(I12) -> 134
A13: Pun vs Double Entendre vs Malapropism | B13: pun vs double entendre | C13: /pun-vs-double-entendre/ | D13: P2 | E13: Figures-of-speech comparison | F13: Pun vs Double Entendre vs Malapropism: Key Differences | G13: Pun vs Double Entendre vs Malapropism | H13: =LEN(G13) -> 37 | I13: Puns, double entendres and malapropisms are often confused. Learn how each figure of speech works and how to tell them apart. | J13: =LEN(I13) -> 125
... A20: Best Books About Puns | B20: books about puns | C20: /books-about-puns/ | D20: P3 | E20: Supplementary; affiliate potential | F20: Best Books About Puns and Wordplay | G20: Best Books About Puns & Wordplay to Read | H20: =LEN(G20) -> 40 | I20: The best books about puns and wordplay for pun lovers, writers and teachers, from pun histories to joke collections. | J20: =LEN(I20) -> 116

Sheet H2 Template
A1: Standard outline for every topic page (replace [X] with the topic)
A2: H1 formula: [Number]+ [X] Puns for [Top Use] That Are [Pun-based quality] e.g. 150+ Cat Puns for Instagram Captions That Are Purr-fectly Funny
A4: Order | B4: Heading | C4: Content Zone | D4: Rule
A5: 1 | B5: Intro (no heading) | C5: Main | D5: 2-sentence declaration: what [X] puns are + where to use them. No story opener.
A6: 2 | B6: [X] Pun One-Liners | C6: Main | D6: Single sentence, twist at the end
A7: 3 | B7: Short [X] Puns | C7: Main | D7: 1-5 words
A8: 4 | B8: Funny [X] Puns | C8: Main | D8: Strongest groaners
A9: 5 | B9: Cute [X] Puns | C9: Main | D9: Soft, sweet tone
A10: 6 | B10: [X] Puns for Instagram Captions | C10: Main | D10: Under ~8 words, standalone; link to Captions hub
A11: 7 | B11: [X] Puns for Kids | C11: Main | D11: Clean Q&A format; link to Kids hub
A12: 8 | B12: [X] Love Puns | C12: Main | D12: Second person; link to Love hub
A13: 9 | B13: [X] Birthday Puns | C13: Main | D13: Occasion-specific; link to Birthday hub
A14: 10 | B14: [X] Pickup Lines | C14: Main | D14: Flirty, clean
A15: 11 | B15: [X] Jokes | C15: Main | D15: Setup + punchline Q&A
A16: 12 | B16: Make Your Own [X] Pun (Pun Generator box) | C16: Border | D16: Embedded generator prefilled with [X]
... A21: 17 | B21: Related Puns (contextual bridges) | C21: Supplementary | D21: Sub-hub + 2 sibling pages, descriptive anchors

Sheet Seasonal Calendar
A1: Event | B1: Event Date | C1: Publish / Refresh By | D1: Pages | E1: Flag
A2: Halloween | B2: 2026-10-31 | C2: ASAP (27 days left) | D2: Halloween, Ghost, Witch, Skeleton, Pumpkin, Bat, Candy, Spider puns | E2: URGENT
A3: Thanksgiving (US) | B3: 2026-11-26 | C3: 2026-10-12 | D3: Thanksgiving, Turkey, Pie puns | E3: Next
A4: Christmas | B4: 2026-12-25 | C4: 2026-11-01 | D4: Christmas, Santa, Snowman, Elf, Reindeer, Cookie puns + Christmas Riddles bridge | E4: Next
A5: New Year | B5: 2027-01-01 | C5: 2026-11-20 | D5: New Year, Gym & Fitness puns
A6: Valentine's Day | B6: 2027-02-14 | C6: 2026-12-20 | D6: Valentine's Day, Love, Chocolate puns
A7: National Pun Day | B7: 2027-03-04 | C7: 2027-01-15 | D7: National Pun Day page; homepage feature
A8: St. Patrick's Day | B8: 2027-03-17 | C8: 2027-01-25 | D8: St. Patrick's Day puns
A9: Easter | B9: 2027-03-28 | C9: 2027-02-01 | D9: Easter, Rabbit, Egg puns
A10: Star Wars Day | B10: 2027-05-04 | C10: 2027-03-15 | D10: Star Wars puns (original wordplay only)
A11: Mother's Day (US) | B11: 2027-05-09 | C11: 2027-03-20 | D11: Mother's Day puns
A12: Graduation season | B12: 2027-05-15 | C12: 2027-03-25 | D12: Graduation puns
A13: Father's Day (US) | B13: 2027-06-20 | C13: 2027-04-25 | D13: Father's Day, Dad Joke puns
A14: Summer | B14: 2027-06-21 | C14: 2027-04-25 | D14: Summer, Beach, Ice Cream, Watermelon puns
A15: Fourth of July | B15: 2027-07-04 | C15: 2027-05-10 | D15: Fourth of July puns
A16: Back to School | B16: 2027-08-15 | C16: 2027-06-20 | D16: School, Teacher puns
A17: Fall | B17: 2027-09-23 | C17: 2027-07-25 | D17: Fall, Apple, Leaf, Corn puns
A19: Rule: publish or refresh 6-8 weeks before the event so pages are indexed before demand peaks.

Sheet Sources
A1: Source | B1: URL | C1: Used For
A2: Punpedia (competitor taxonomy benchmark) | B2: https://punpedia.org/ | C2: Category and topic coverage of an established pun site
A3: Flick: caption pun pages | B3: https://www.flick.social/captions/sports-puns-for-instagram-captions | C3: Caption pages built on best / short / funny / cute modifiers
A4: SuperSummary: Pun | B4: https://www.supersummary.com/pun/ | C4: Pun types (homophonic, homographic, homonymic, compound, recursive, visual)
A5: Lems: Teaching English using puns | B5: https://www.scribd.com/doc/179238494/Puns | C5: Texting puns as a pun category
A6: Verbivore: National Pun Day | B6: https://verbivore.com/?p=4784582 | C6: National Pun Day on March 4
A7: Punscrazy (competitor model) | B7: https://community.adobe.com/questions-712/can-anyone-help-me-to-imrove-punscrazy-com-1630608 | C7: Competitor mixing puns, jokes and slang meanings
A8: craftypuns.net indexed pages | B8: https://craftypuns.net/ | C8: Pages marked Live (verified)
